<?xml version="1.0" ?>
<sdf version="1.10">
    <world name="car_world">
        <physics name="1ms" type="ignored">
            <max_step_size>0.001</max_step_size>
            <real_time_factor>1.0</real_time_factor>
        </physics>
        <plugin
            filename="gz-sim-physics-system"
            name="gz::sim::systems::Physics">
        </plugin>
        <plugin
            filename="gz-sim-user-commands-system"
            name="gz::sim::systems::UserCommands">
        </plugin>
        <plugin
            filename="gz-sim-scene-broadcaster-system"
            name="gz::sim::systems::SceneBroadcaster">
        </plugin>
        <plugin
          filename="gz-sim-sensors-system"
          name="gz::sim::systems::Sensors">
          <render_engine>ogre2</render_engine>
        </plugin>

        <light type="directional" name="sun">
            <cast_shadows>true</cast_shadows>
            <pose>0 0 10 0 0 0</pose>
            <diffuse>0.8 0.8 0.8 1</diffuse>
            <specular>0.2 0.2 0.2 1</specular>
            <attenuation>
                <range>1000</range>
                <constant>0.9</constant>
                <linear>0.01</linear>
                <quadratic>0.001</quadratic>
            </attenuation>
            <direction>-0.5 0.1 -0.9</direction>
        </light>

        <model name="ground_plane">
            <static>true</static>
            <link name="link">
                <collision name="collision">
                <geometry>
                    <plane>
                    <normal>0 0 1</normal>
                    </plane>
                </geometry>
                </collision>
                <visual name="visual">
                <geometry>
                    <plane>
                    <normal>0 0 1</normal>
                    <size>100 100</size>
                    </plane>
                </geometry>
                <material>
                    <ambient>0.8 0.8 0.8 1</ambient>
                    <diffuse>0.8 0.8 0.8 1</diffuse>
                    <specular>0.8 0.8 0.8 1</specular>
                </material>
                </visual>
            </link>
        </model>

        <model name='vehicle_blue' canonical_link='chassis'>
          <plugin
              filename="gz-sim-diff-drive-system"
              name="gz::sim::systems::DiffDrive">
              <left_joint>front_left_wheel_joint</left_joint>
              <left_joint>back_left_wheel_joint</left_joint>
              <right_joint>front_right_wheel_joint</right_joint>
              <right_joint>back_right_wheel_joint</right_joint>
              <wheel_separation>1.2</wheel_separation>
              <wheel_radius>0.4</wheel_radius>
              <odom_publish_frequency>1</odom_publish_frequency>
              <topic>cmd_vel</topic>
          </plugin>
          <!-- Moving Forward-->
          <plugin filename="gz-sim-triggered-publisher-system"
                  name="gz::sim::systems::TriggeredPublisher">
              <input type="gz.msgs.Int32" topic="/keyboard/keypress">
                  <match field="data">16777235</match>
              </input>
              <output type="gz.msgs.Twist" topic="/cmd_vel">
                  linear: {x: 0.5}, angular: {z: 0.0}
              </output>
          </plugin>

          <pose relative_to='world'>0 0 0 0 0 0</pose>
      
          <frame name="lidar_frame" attached_to='chassis'>
              <pose>0.8 0 0.5 0 0 0</pose>
          </frame>
          <link name='chassis'>
            <pose relative_to='__model__'>0.5 0 0.4 0 0 0</pose>
            <inertial> <!--inertial properties of the link mass, inertia matix-->
              <mass>1.14395</mass>
              <inertia>
                <ixx>0.095329</ixx>
                <ixy>0</ixy>
                <ixz>0</ixz>
                <iyy>0.381317</iyy>
                <iyz>0</iyz>
                <izz>0.476646</izz>
              </inertia>
            </inertial>
            <visual name='visual'>
                <geometry>
                    <box>
                        <size>2.0 1.0 0.5</size>
                    </box>
                </geometry>
                <!--let's add color to our link-->
                <material>
                    <ambient>0.0 0.0 1.0 1</ambient>
                    <diffuse>0.0 0.0 1.0 1</diffuse>
                    <specular>0.0 0.0 1.0 1</specular>
                </material>
            </visual>
            <collision name='collision'>
                <geometry>
                    <box>
                        <size>2.0 1.0 0.5</size>
                    </box>
                </geometry>
            </collision>
            <sensor name='gpu_lidar' type='gpu_lidar'>"
                <pose relative_to='lidar_frame'>0 0 0 0 0 0</pose>
                <topic>lidar</topic>
                <update_rate>20</update_rate>
                <ray>
                    <scan>
                        <horizontal>
                            <samples>666</samples>
                            <resolution>1</resolution>
                            <min_angle>-1.91986</min_angle>
                            <max_angle>1.9186</max_angle>
                        </horizontal>
                    </scan>
                    <range>
                        <min>0.08</min>
                        <max>25</max>
                        <resolution>0.01</resolution>
                    </range>
                </ray>
                <always_on>1</always_on>
                <visualize>true</visualize>
            </sensor>
          </link>
          <!--Back left wheel-->
          <link name='back_left_wheel'>
              <pose relative_to="chassis">-0.5 0.6 0 -1.5707 0 0</pose>
              <inertial>
                  <mass>1</mass>
                  <inertia>
                      <ixx>0.043333</ixx>
                      <ixy>0</ixy>
                      <ixz>0</ixz>
                      <iyy>0.043333</iyy>
                      <iyz>0</iyz>
                      <izz>0.08</izz>
                  </inertia>
              </inertial>
              <visual name='visual'>
                  <geometry>
                      <cylinder>
                          <radius>0.4</radius>
                          <length>0.2</length>
                      </cylinder>
                  </geometry>
                  <material>
                      <ambient>1.0 0.0 0.0 1</ambient>
                      <diffuse>1.0 0.0 0.0 1</diffuse>
                      <specular>1.0 0.0 0.0 1</specular>
                  </material>
              </visual>
              <collision name='collision'>
                  <geometry>
                      <cylinder>
                          <radius>0.4</radius>
                          <length>0.2</length>
                      </cylinder>
                  </geometry>
              </collision>
          </link>
          <joint name='back_left_wheel_joint' type='revolute'>
              <pose relative_to='back_left_wheel'/>
              <parent>chassis</parent>
              <child>back_left_wheel</child>
              <axis>
                  <xyz expressed_in='__model__'>0 1 0</xyz> <!--can be defined as any frame or even arbitrary frames-->
                  <limit>
                      <lower>-1.79769e+308</lower>    <!--negative infinity-->
                      <upper>1.79769e+308</upper>     <!--positive infinity-->
                  </limit>
              </axis>
          </joint>
          <!--Back Right wheel-->
          <link name='back_right_wheel'>
              <pose relative_to="chassis">-0.5 -0.6 0 -1.5707 0 0</pose> <!--angles are in radian-->
              <inertial>
                  <mass>1</mass>
                  <inertia>
                      <ixx>0.043333</ixx>
                      <ixy>0</ixy>
                      <ixz>0</ixz>
                      <iyy>0.043333</iyy>
                      <iyz>0</iyz>
                      <izz>0.08</izz>
                  </inertia>
              </inertial>
              <visual name='visual'>
                  <geometry>
                      <cylinder>
                          <radius>0.4</radius>
                          <length>0.2</length>
                      </cylinder>
                  </geometry>
                  <material>
                      <ambient>1.0 0.0 0.0 1</ambient>
                      <diffuse>1.0 0.0 0.0 1</diffuse>
                      <specular>1.0 0.0 0.0 1</specular>
                  </material>
              </visual>
              <collision name='collision'>
                  <geometry>
                      <cylinder>
                          <radius>0.4</radius>
                          <length>0.2</length>
                      </cylinder>
                  </geometry>
              </collision>
          </link>
          <joint name='back_right_wheel_joint' type='revolute'>
              <pose relative_to='back_right_wheel'/>
              <parent>chassis</parent>
              <child>back_right_wheel</child>
              <axis>
                  <xyz expressed_in='__model__'>0 1 0</xyz> <!--can be defined as any frame or even arbitrary frames-->
                  <limit>
                      <lower>-1.79769e+308</lower>    <!--negative infinity-->
                      <upper>1.79769e+308</upper>     <!--positive infinity-->
                  </limit>
              </axis>
          </joint>
          <!--Front left wheel-->
          <link name='front_left_wheel'>
              <pose relative_to="chassis">0.5 0.6 0 -1.5707 0 0</pose>
              <inertial>
                  <mass>1</mass>
                  <inertia>
                      <ixx>0.043333</ixx>
                      <ixy>0</ixy>
                      <ixz>0</ixz>
                      <iyy>0.043333</iyy>
                      <iyz>0</iyz>
                      <izz>0.08</izz>
                  </inertia>
              </inertial>
              <visual name='visual'>
                  <geometry>
                      <cylinder>
                          <radius>0.4</radius>
                          <length>0.2</length>
                      </cylinder>
                  </geometry>
                  <material>
                      <ambient>1.0 0.0 0.0 1</ambient>
                      <diffuse>1.0 0.0 0.0 1</diffuse>
                      <specular>1.0 0.0 0.0 1</specular>
                  </material>
              </visual>
              <collision name='collision'>
                  <geometry>
                      <cylinder>
                          <radius>0.4</radius>
                          <length>0.2</length>
                      </cylinder>
                  </geometry>
              </collision>
          </link>
          <joint name='front_left_wheel_joint' type='revolute'>
              <pose relative_to='front_left_wheel'/>
              <parent>chassis</parent>
              <child>front_left_wheel</child>
              <axis>
                  <xyz expressed_in='__model__'>0 1 0</xyz> <!--can be defined as any frame or even arbitrary frames-->
                  <limit>
                      <lower>-1.79769e+308</lower>    <!--negative infinity-->
                      <upper>1.79769e+308</upper>     <!--positive infinity-->
                  </limit>
              </axis>
          </joint>
          <!--Front right wheel-->
          <link name='front_right_wheel'>
              <pose relative_to="chassis">0.5 -0.6 0 -1.5707 0 0</pose>
              <inertial>
                  <mass>1</mass>
                  <inertia>
                      <ixx>0.043333</ixx>
                      <ixy>0</ixy>
                      <ixz>0</ixz>
                      <iyy>0.043333</iyy>
                      <iyz>0</iyz>
                      <izz>0.08</izz>
                  </inertia>
              </inertial>
              <visual name='visual'>
                  <geometry>
                      <cylinder>
                          <radius>0.4</radius>
                          <length>0.2</length>
                      </cylinder>
                  </geometry>
                  <material>
                      <ambient>1.0 0.0 0.0 1</ambient>
                      <diffuse>1.0 0.0 0.0 1</diffuse>
                      <specular>1.0 0.0 0.0 1</specular>
                  </material>
              </visual>
              <collision name='collision'>
                  <geometry>
                      <cylinder>
                          <radius>0.4</radius>
                          <length>0.2</length>
                      </cylinder>
                  </geometry>
              </collision>
          </link>
          <joint name='front_right_wheel_joint' type='revolute'>
              <pose relative_to='front_right_wheel'/>
              <parent>chassis</parent>
              <child>front_right_wheel</child>
              <axis>
                  <xyz expressed_in='__model__'>0 1 0</xyz> <!--can be defined as any frame or even arbitrary frames-->
                  <limit>
                      <lower>-1.79769e+308</lower>    <!--negative infinity-->
                      <upper>1.79769e+308</upper>     <!--positive infinity-->
                  </limit>
              </axis>
          </joint>
        </model>
      <!--wall-->
        <model name='wall'>
            <static>true</static>
            <pose>5 0 0 0 0 0</pose><!--pose relative to the world-->
            <link name='box'>
                <pose/>
                <inertial> <!--inertial properties of the link mass, inertia matix-->
                    <mass>1.14395</mass>
                    <inertia>
                        <ixx>9.532917</ixx>
                        <ixy>0</ixy>
                        <ixz>0</ixz>
                        <iyy>0.023832</iyy>
                        <iyz>0</iyz>
                        <izz>9.556749</izz>
                    </inertia>
                </inertial>
                <visual name='visual'>
                    <geometry>
                        <box>
                            <size>0.5 10.0 2.0</size>
                        </box>
                    </geometry>
                    <!--let's add color to our link-->
                    <material>
                        <ambient>0.0 0.0 1.0 1</ambient>
                        <diffuse>0.0 0.0 1.0 1</diffuse>
                        <specular>0.0 0.0 1.0 1</specular>
                    </material>
                </visual>
                <collision name='collision'> <!--todo: describe why we need the collision-->
                    <geometry>
                        <box>
                            <size>0.5 10.0 2.0</size>
                        </box>
                    </geometry>
                </collision>
                <sensor name='sensor_contact' type='contact'>
                    <contact>
                        <collision>collision</collision>
                    </contact>
                </sensor>
            </link>
            <plugin filename="gz-sim-touchplugin-system"
                    name="gz::sim::systems::TouchPlugin">
                <target>vehicle_blue</target>
                <namespace>wall</namespace>
                <time>0.001</time>
                <enabled>true</enabled>
            </plugin>
        </model>
    </world>
</sdf>
